{"uuid": "06f9ee7b-3277-4b03-951b-3f2f5af08e94", "children": ["53fe82fc-d290-4360-9657-b41a780a5651"], "befores": [{"name": "refresh", "status": "passed", "start": 1645584718562, "stop": 1645584718562}], "afters": [{"name": "refresh::0", "status": "broken", "statusDetails": {"message": "urllib3.exceptions.MaxRetryError: HTTPConnectionPool(host='127.0.0.1', port=52264): Max retries exceeded with url: /session/ba925fc69bf2ab59fb8c09e2c3b88b00/refresh (Caused by NewConnectionError('<urllib3.connection.HTTPConnection object at 0x7fdb400ebca0>: Failed to establish a new connection: [Errno 61] Connection refused'))\n", "trace": "  File \"/Users/a58/Desktop/58collegebackground/venv/lib/python3.8/site-packages/allure_commons/_allure.py\", line 200, in __call__\n    return self._fixture_function(*args, **kwargs)\n  File \"/Users/a58/Desktop/58collegebackground/venv/lib/python3.8/site-packages/_pytest/fixtures.py\", line 941, in _teardown_yield_fixture\n    next(it)\n  File \"/Users/a58/Desktop/auto58/web_ui_test/pytest_Web_Framework_V1/TestCases/conftest.py\", line 79, in refresh\n    access_web.refresh()\n  File \"/Users/a58/Desktop/58collegebackground/venv/lib/python3.8/site-packages/selenium/webdriver/remote/webdriver.py\", line 831, in refresh\n    self.execute(Command.REFRESH)\n  File \"/Users/a58/Desktop/58collegebackground/venv/lib/python3.8/site-packages/selenium/webdriver/remote/webdriver.py\", line 319, in execute\n    response = self.command_executor.execute(driver_command, params)\n  File \"/Users/a58/Desktop/58collegebackground/venv/lib/python3.8/site-packages/selenium/webdriver/remote/remote_connection.py\", line 374, in execute\n    return self._request(command_info[0], url, body=data)\n  File \"/Users/a58/Desktop/58collegebackground/venv/lib/python3.8/site-packages/selenium/webdriver/remote/remote_connection.py\", line 397, in _request\n    resp = self._conn.request(method, url, body=body, headers=headers)\n  File \"/Users/a58/Desktop/58collegebackground/venv/lib/python3.8/site-packages/urllib3/request.py\", line 78, in request\n    return self.request_encode_body(\n  File \"/Users/a58/Desktop/58collegebackground/venv/lib/python3.8/site-packages/urllib3/request.py\", line 170, in request_encode_body\n    return self.urlopen(method, url, **extra_kw)\n  File \"/Users/a58/Desktop/58collegebackground/venv/lib/python3.8/site-packages/urllib3/poolmanager.py\", line 375, in urlopen\n    response = conn.urlopen(method, u.request_uri, **kw)\n  File \"/Users/a58/Desktop/58collegebackground/venv/lib/python3.8/site-packages/urllib3/connectionpool.py\", line 783, in urlopen\n    return self.urlopen(\n  File \"/Users/a58/Desktop/58collegebackground/venv/lib/python3.8/site-packages/urllib3/connectionpool.py\", line 783, in urlopen\n    return self.urlopen(\n  File \"/Users/a58/Desktop/58collegebackground/venv/lib/python3.8/site-packages/urllib3/connectionpool.py\", line 783, in urlopen\n    return self.urlopen(\n  File \"/Users/a58/Desktop/58collegebackground/venv/lib/python3.8/site-packages/urllib3/connectionpool.py\", line 755, in urlopen\n    retries = retries.increment(\n  File \"/Users/a58/Desktop/58collegebackground/venv/lib/python3.8/site-packages/urllib3/util/retry.py\", line 574, in increment\n    raise MaxRetryError(_pool, url, error or ResponseError(cause))\n"}, "start": 1645584722698, "stop": 1645584722713}], "start": 1645584718562, "stop": 1645584722713}